Workbook

Sheet Summary
A1: AgentGuard Risk & Vulnerability Catalog | B1: AgentGuard Risk & Vulnerability Catalog | C1: AgentGuard Risk & Vulnerability Catalog | D1: AgentGuard Risk & Vulnerability Catalog | E1: AgentGuard Risk & Vulnerability Catalog | F1: AgentGuard Risk & Vulnerability Catalog | G1: AgentGuard Risk & Vulnerability Catalog | H1: AgentGuard Risk & Vulnerability Catalog | I1: AgentGuard Risk & Vulnerability Catalog | J1: AgentGuard Risk & Vulnerability Catalog | K1: AgentGuard Risk & Vulnerability Catalog | L1: AgentGuard Risk & Vulnerability Catalog | M1: AgentGuard Risk & Vulnerability Catalog | N1: AgentGuard Risk & Vulnerability Catalog | O1: AgentGuard Risk & Vulnerability Catalog | P1: AgentGuard Risk & Vulnerability Catalog | Q1: AgentGuard Risk & Vulnerability Catalog
A2: AgentGuard Risk & Vulnerability Catalog | B2: AgentGuard Risk & Vulnerability Catalog | C2: AgentGuard Risk & Vulnerability Catalog | D2: AgentGuard Risk & Vulnerability Catalog | E2: AgentGuard Risk & Vulnerability Catalog | F2: AgentGuard Risk & Vulnerability Catalog | G2: AgentGuard Risk & Vulnerability Catalog | H2: AgentGuard Risk & Vulnerability Catalog | I2: AgentGuard Risk & Vulnerability Catalog | J2: AgentGuard Risk & Vulnerability Catalog | K2: AgentGuard Risk & Vulnerability Catalog | L2: AgentGuard Risk & Vulnerability Catalog | M2: AgentGuard Risk & Vulnerability Catalog | N2: AgentGuard Risk & Vulnerability Catalog | O2: AgentGuard Risk & Vulnerability Catalog | P2: AgentGuard Risk & Vulnerability Catalog | Q2: AgentGuard Risk & Vulnerability Catalog
A3: Formula-driven overview of native AgentGuard, custom, and NVIDIA SkillSpector rules
A5: Total Rules | B5: AgentGuard Engine | C5: SkillSpector Engine | D5: Critical | E5: High | F5: Native Rules
A6: =COUNTA('Risk_rule Catalog'!$A$2:$A$182) -> 181 | B6: =COUNTIF('Risk_rule Catalog'!$C$2:$C$182,"agentguard") -> 113 | C6: =COUNTIF('Risk_rule Catalog'!$C$2:$C$182,"skillspector") -> 68 | D6: =COUNTIF('Risk_rule Catalog'!$F$2:$F$182,"Critical") -> 73 | E6: =COUNTIF('Risk_rule Catalog'!$F$2:$F$182,"High") -> 83 | F6: =COUNTIF('Risk_rule Catalog'!$D$2:$D$182,"Native") -> 112
A8: Severity | B8: Rule Count | D8: Analysis Type | E8: Rule Count | G8: Rule Set | H8: Rule Count
A9: Critical | B9: =COUNTIF('Risk_rule Catalog'!$F$2:$F$182,A9) -> 73 | D9: taint | E9: =COUNTIF('Risk_rule Catalog'!$G$2:$G$182,D9) -> 75 | G9: Native | H9: =COUNTIF('Risk_rule Catalog'!$D$2:$D$182,G9) -> 112
A10: High | B10: =COUNTIF('Risk_rule Catalog'!$F$2:$F$182,A10) -> 83 | D10: config | E10: =COUNTIF('Risk_rule Catalog'!$G$2:$G$182,D10) -> 22 | G10: Custom | H10: =COUNTIF('Risk_rule Catalog'!$D$2:$D$182,G10) -> 1
A11: Medium | B11: =COUNTIF('Risk_rule Catalog'!$F$2:$F$182,A11) -> 22 | D11: external | E11: =COUNTIF('Risk_rule Catalog'!$G$2:$G$182,D11) -> 68 | G11: Integration | H11: =COUNTIF('Risk_rule Catalog'!$D$2:$D$182,G11) -> 68
A12: Low | B12: =COUNTIF('Risk_rule Catalog'!$F$2:$F$182,A12) -> 3 | D12: secret | E12: =COUNTIF('Risk_rule Catalog'!$G$2:$G$182,D12) -> 5
D13: structural | E13: =COUNTIF('Risk_rule Catalog'!$G$2:$G$182,D13) -> 4
D14: control_flow | E14: =COUNTIF('Risk_rule Catalog'!$G$2:$G$182,D14) -> 4
D15: dependency | E15: =COUNTIF('Risk_rule Catalog'!$G$2:$G$182,D15) -> 3
A18: Catalog Scope | B18: Catalog Scope | C18: Catalog Scope | D18: Catalog Scope | E18: Catalog Scope | F18: Catalog Scope | G18: Catalog Scope | H18: Catalog Scope
A19: Includes all YAML rule definitions currently loaded from rules/builtin, rules/custom, and rules/integrations. SkillSpector entries are external-engine metadata and require the separately installed NVIDIA CLI. | B19: Includes all YAML rule definitions currently loaded from rules/builtin, rules/custom, and rules/integrations. SkillSpector entries are external-engine metadata and require the separately installed NVIDIA CLI. | C19: Includes all YAML rule definitions currently loaded from rules/builtin, rules/custom, and rules/integrations. SkillSpector entries are external-engine metadata and require the separately installed NVIDIA CLI. | D19: Includes all YAML rule definitions currently loaded from rules/builtin, rules/custom, and rules/integrations. SkillSpector entries are external-engine metadata and require the separately installed NVIDIA CLI. | E19: Includes all YAML rule definitions currently loaded from rules/builtin, rules/custom, and rules/integrations. SkillSpector entries are external-engine metadata and require the separately installed NVIDIA CLI. | F19: Includes all YAML rule definitions currently loaded from rules/builtin, rules/custom, and rules/integrations. SkillSpector entries are external-engine metadata and require the separately installed NVIDIA CLI. | G19: Includes all YAML rule definitions currently loaded from rules/builtin, rules/custom, and rules/integrations. SkillSpector entries are external-engine metadata and require the separately installed NVIDIA CLI. | H19: Includes all YAML rule definitions currently loaded from rules/builtin, rules/custom, and rules/integrations. SkillSpector entries are external-engine metadata and require the separately installed NVIDIA CLI.
A20: Includes all YAML rule definitions currently loaded from rules/builtin, rules/custom, and rules/integrations. SkillSpector entries are external-engine metadata and require the separately installed NVIDIA CLI. | B20: Includes all YAML rule definitions currently loaded from rules/builtin, rules/custom, and rules/integrations. SkillSpector entries are external-engine metadata and require the separately installed NVIDIA CLI. | C20: Includes all YAML rule definitions currently loaded from rules/builtin, rules/custom, and rules/integrations. SkillSpector entries are external-engine metadata and require the separately installed NVIDIA CLI. | D20: Includes all YAML rule definitions currently loaded from rules/builtin, rules/custom, and rules/integrations. SkillSpector entries are external-engine metadata and require the separately installed NVIDIA CLI. | E20: Includes all YAML rule definitions currently loaded from rules/builtin, rules/custom, and rules/integrations. SkillSpector entries are external-engine metadata and require the separately installed NVIDIA CLI. | F20: Includes all YAML rule definitions currently loaded from rules/builtin, rules/custom, and rules/integrations. SkillSpector entries are external-engine metadata and require the separately installed NVIDIA CLI. | G20: Includes all YAML rule definitions currently loaded from rules/builtin, rules/custom, and rules/integrations. SkillSpector entries are external-engine metadata and require the separately installed NVIDIA CLI. | H20: Includes all YAML rule definitions currently loaded from rules/builtin, rules/custom, and rules/integrations. SkillSpector entries are external-engine metadata and require the separately installed NVIDIA CLI.
A21: https://github.com/akarshkn17/AgentGuard | B21: https://github.com/akarshkn17/AgentGuard | C21: https://github.com/akarshkn17/AgentGuard | D21: https://github.com/akarshkn17/AgentGuard | E21: https://github.com/akarshkn17/AgentGuard | F21: https://github.com/akarshkn17/AgentGuard | G21: https://github.com/akarshkn17/AgentGuard | H21: https://github.com/akarshkn17/AgentGuard

Sheet Risk_rule Catalog
A1: Rule ID | B1: Name | C1: Engine | D1: Rule Set | E1: Category | F1: Severity | G1: Analysis Type | H1: Targets | I1: Sources | J1: Sinks | K1: Barriers | L1: Message | M1: Detection Logic | N1: Remediation | O1: Source Description | P1: Sink Description | Q1: Source File | R1: Source URL | S1: Mapped Security Controls
A2: CUSTOM-AI-001 | B2: Example organization admin command rule | C2: agentguard | D2: Custom | E2: custom | F2: Critical | G2: taint | H2: agent, tool | I2: llm_output | J2: shell_execution | K2: command_allowlist, authorization_check | L2: LLM output reaches a custom privileged command API. | N2: Use a fixed operation enum and deterministic authorization before execution. | Q2: rules/custom/example.yaml | R2: https://github.com/akarshkn17/AgentGuard/blob/main/rules/custom/example.yaml | S2: SEC_06 (Structured Output Schema + Tool Name Auth); IAM_04 (User Identity Propagation - AgentAuthContext); SEC_18 (Human-in-the-Loop for High-Risk Actions); MON_04 (Tool Invocation Monitoring + Auto-Response); IR_01 (Multi-Level Kill-Switch Model)
A3: AIR-AGENT-001 | B3: Unbounded recursion or iteration in agent loop | C3: agentguard | D3: Native | E3: Agent Orchestration | F3: High | G3: config | H3: agent | L3: Unbounded recursion or iteration in agent loop | M3: Flag agent loops lacking max iterations/recursion limit or set to extremely high/unlimited. | N3: Hard step/recursion limit | O3: N/A | P3: while agent continues, recursion_limit absent/excessive | Q3: rules/builtin/agent_orchestration.yaml | R3: https://github.com/akarshkn17/AgentGuard/blob/main/rules/builtin/agent_orchestration.yaml | S3: SEC_16 (Recursive Loop & Runaway Prevention); BIZ_06 (Cost and Abuse Budgeting); MON_08 (Behavioral Analytics & Anomaly Detection); IR_01 (Multi-Level Kill-Switch Model)
A4: AIR-AGENT-002 | B4: Unbounded retry of LLM/tool calls | C4: agentguard | D4: Native | E4: Agent Orchestration | F4: High | G4: config | H4: agent | L4: Unbounded retry of LLM/tool calls | M4: Flag retry decorators/loops with no max attempts around model/tool/network calls. | N4: Max retry count + timeout + budget | O4: N/A | P4: retry loops/backoff handlers | Q4: rules/builtin/agent_orchestration.yaml | R4: https://github.com/akarshkn17/AgentGuard/blob/main/rules/builtin/agent_orchestration.yaml | S4: SEC_16 (Recursive Loop & Runaway Prevention); BIZ_06 (Cost and Abuse Budgeting); MON_08 (Behavioral Analytics & Anomaly Detection); IR_01 (Multi-Level Kill-Switch Model)
A5: AIR-AGENT-003 | B5: No timeout on external tool or model call | C5: agentguard | D5: Native | E5: Agent Orchestration | F5: Medium | G5: config | H5: agent | J5: shell_execution | L5: No timeout on external tool or model call | M5: Flag external calls in agent/tool code with absent timeout where API supports one; confidence-based. | N5: Finite timeout | O5: N/A | P5: HTTP/model/subprocess/tool call | Q5: rules/builtin/agent_orchestration.yaml | R5: https://github.com/akarshkn17/AgentGuard/blob/main/rules/builtin/agent_orchestration.yaml | S5: SEC_16 (Recursive Loop & Runaway Prevention); BIZ_06 (Cost and Abuse Budgeting); MON_08 (Behavioral Analytics & Anomaly Detection); IR_01 (Multi-Level Kill-Switch Model)
A6: AIR-AGENT-004 | B6: No token/context budget before model invocation | C6: agentguard | D6: Native | E6: Agent Orchestration | F6: High | G6: config | H6: agent | L6: No token/context budget before model invocation | M6: Flag unbounded collection/history/document concatenation into prompts with no length/token cap. | N6: Maximum input size/token budget/truncation | O6: Documents/history/retrieval context | P6: LLM invocation | Q6: rules/builtin/agent_orchestration.yaml | R6: https://github.com/akarshkn17/AgentGuard/blob/main/rules/builtin/agent_orchestration.yaml | S6: SEC_07 (Token Budget Monitoring - Prompt Stuffing Defense); BIZ_06 (Cost and Abuse Budgeting); MON_08 (Behavioral Analytics & Anomaly Detection)
A7: AIR-AGENT-005 | B7: Parallel agents share mutable global state | C7: agentguard | D7: Native | E7: Agent Orchestration | F7: High | G7: structural | H7: agent | L7: Parallel agents share mutable global state | M7: Flag global mutable conversation/memory/tool state accessed by concurrent agent handlers. | N7: Per-session isolated state store | O7: Multiple sessions/agents | P7: module/global mutable dict/list/state object | Q7: rules/builtin/agent_orchestration.yaml | R7: https://github.com/akarshkn17/AgentGuard/blob/main/rules/builtin/agent_orchestration.yaml | S7: REG_02 (Agent Manifest Schema Validation); MEM_01 (Memory Store Classification and Ownership); MEM_02 (Memory Read Authorization and ACL Filtering); MON_08 (Behavioral Analytics & Anomaly Detection)
A8: AIR-AGENT-006 | B8: Model output selects arbitrary callable/function by name | C8: agentguard | D8: Native | E8: Agent Orchestration | F8: Critical | G8: taint | H8: agent | I8: llm_output | K8: allowlist | L8: Model output selects arbitrary callable/function by name | M8: Flag model-controlled name used in dynamic callable lookup/invocation without allowlist. | N8: Allowlisted registry with fixed capability set | O8: LLM output function/tool name | P8: globals(), getattr(), registry lookup followed by call | Q8: rules/builtin/agent_orchestration.yaml | R8: https://github.com/akarshkn17/AgentGuard/blob/main/rules/builtin/agent_orchestration.yaml | S8: SEC_06 (Structured Output Schema + Tool Name Auth); REG_02 (Agent Manifest Schema Validation); SEC_21 (Policy-as-Code for AI Controls); MON_04 (Tool Invocation Monitoring + Auto-Response); IR_01 (Multi-Level Kill-Switch Model)
A9: AIR-AGENT-007 | B9: Agent can dynamically install/load new tools during execution | C9: agentguard | D9: Native | E9: Agent Orchestration | F9: Critical | G9: taint | H9: agent | I9: llm_output, user_input | L9: Agent can dynamically install/load new tools during execution | M9: Flag model/user-controlled dynamic tool registration, package install, plugin load, or MCP server connection. | N9: Admin-approved signed registry only | O9: Model/user tool/package/server identifier | P9: tool installer/registry/import/MCP connect | Q9: rules/builtin/agent_orchestration.yaml | R9: https://github.com/akarshkn17/AgentGuard/blob/main/rules/builtin/agent_orchestration.yaml | S9: REG_01 (Authoritative Agent Registry); REG_03 (AIBOM Required for Every Agent); SEC_15 (Agent Registry Compliance Gate); REG_07 (Runtime Drift Detection Against Registry); SEC_20 (AIBOM - AI Bill of Materials); IR_01 (Multi-Level Kill-Switch Model)
A10: AIR-AGENT-008 | B10: Planner-generated arguments bypass typed tool interface | C10: agentguard | D10: Native | E10: Agent Orchestration | F10: High | G10: taint | H10: agent | I10: llm_output | K10: schema_validation | L10: Planner-generated arguments bypass typed tool interface | M10: Flag generic dispatcher that forwards model-produced dicts to callables without per-tool validation. | N10: Per-tool typed schema and validation | O10: Planner raw text/JSON | P10: generic dispatch **kwargs/dict to arbitrary tool | Q10: rules/builtin/agent_orchestration.yaml | R10: https://github.com/akarshkn17/AgentGuard/blob/main/rules/builtin/agent_orchestration.yaml | S10: SEC_06 (Structured Output Schema + Tool Name Auth); REG_02 (Agent Manifest Schema Validation); SEC_21 (Policy-as-Code for AI Controls); MON_04 (Tool Invocation Monitoring + Auto-Response)
A11: AIR-AGENT-009 | B11: Sub-agent can call parent-only privileged tools | C11: agentguard | D11: Native | E11: Agent Orchestration | F11: Critical | G11: config | H11: multi-agent | L11: Sub-agent can call parent-only privileged tools | M11: Build agent-to-tool graph; flag privileged tool bound to or reachable by unauthorized sub-agents. | N11: Per-agent capability set | O11: Sub-agent execution context | P11: privileged parent tool | Q11: rules/builtin/agent_orchestration.yaml | R11: https://github.com/akarshkn17/AgentGuard/blob/main/rules/builtin/agent_orchestration.yaml | S11: IAM_03 (Least-Privilege Resource-Scoped IAM); IAM_14 (Agent-to-Agent Trust Scoping); REG_02 (Agent Manifest Schema Validation); SEC_15 (Agent Registry Compliance Gate); MON_04 (Tool Invocation Monitoring + Auto-Response); IR_01 (Multi-Level Kill-Switch Model)
A12: AIR-AGENT-010 | B12: Agent-to-agent messages can spoof system/internal role | C12: agentguard | D12: Native | E12: Agent Orchestration | F12: Critical | G12: taint | H12: multi-agent | L12: Agent-to-agent messages can spoof system/internal role | M12: Flag remote agent content accepted with caller-supplied privileged role/type. | N12: Authenticated channel + fixed role assignment | O12: Remote/sub-agent message | P12: system/internal message channel | Q12: rules/builtin/agent_orchestration.yaml | R12: https://github.com/akarshkn17/AgentGuard/blob/main/rules/builtin/agent_orchestration.yaml | S12: IAM_05 (A2A Delegation Bundle Validation); IAM_14 (Agent-to-Agent Trust Scoping); SEC_04 (A2A Inbound Content Filtering); MON_03 (Decision Trace Logging - Tool, Policy and Evidence Trace); IR_01 (Multi-Level Kill-Switch Model)
A13: AIR-AUTH-001 | B13: Tool authorization does not bind to initiating user identity | C13: agentguard | D13: Native | E13: Authorization | F13: Critical | G13: control_flow | H13: agent, tool | K13: rbac_check | L13: Tool authorization does not bind to initiating user identity | M13: Flag sensitive tool functions lacking user/principal parameter or authorization call before side effect. | N13: Propagate identity and enforce RBAC/ABAC at tool boundary | O13: Authenticated user identity | P13: sensitive tool handler | Q13: rules/builtin/authorization.yaml | R13: https://github.com/akarshkn17/AgentGuard/blob/main/rules/builtin/authorization.yaml | S13: IAM_04 (User Identity Propagation - AgentAuthContext); IAM_03 (Least-Privilege Resource-Scoped IAM); MON_03 (Decision Trace Logging - Tool, Policy and Evidence Trace); SEC_18 (Human-in-the-Loop for High-Risk Actions)
A14: AIR-AUTH-002 | B14: Cross-agent delegation drops authorization context | C14: agentguard | D14: Native | E14: Authorization | F14: Critical | G14: taint | H14: multi-agent | L14: Cross-agent delegation drops authorization context | M14: Track identity object across agent call graph; flag delegation where identity is absent/replaced with service identity only. | N14: Propagate signed identity/claims and reduce privileges | O14: User principal/claims/tenant | P14: sub-agent invocation / remote agent call | Q14: rules/builtin/authorization.yaml | R14: https://github.com/akarshkn17/AgentGuard/blob/main/rules/builtin/authorization.yaml | S14: IAM_05 (A2A Delegation Bundle Validation); IAM_04 (User Identity Propagation - AgentAuthContext); IAM_14 (Agent-to-Agent Trust Scoping); IAM_13 (Federated Identity Subject Consistency Verification); MON_03 (Decision Trace Logging - Tool, Policy and Evidence Trace); IR_01 (Multi-Level Kill-Switch Model)
A15: AIR-AUTH-003 | B15: Agent identity trusted from spoofable header/string | C15: agentguard | D15: Native | E15: Identity | F15: Critical | G15: taint | H15: agent, tool, mcp | I15: user_input | J15: authorization_decision | L15: Agent identity trusted from spoofable header/string | M15: Flag request/model-controlled identity strings used in allow/deny checks. | N15: Verified signed token/workload identity | O15: X-Agent-Name, agent_id, role, caller name from request/model | P15: authorization decision | Q15: rules/builtin/identity.yaml | R15: https://github.com/akarshkn17/AgentGuard/blob/main/rules/builtin/identity.yaml | S15: IAM_13 (Federated Identity Subject Consistency Verification); IAM_05 (A2A Delegation Bundle Validation); IAM_04 (User Identity Propagation - AgentAuthContext); MON_03 (Decision Trace Logging - Tool, Policy and Evidence Trace); IR_01 (Multi-Level Kill-Switch Model)
A16: AIR-AUTH-004 | B16: Runtime service account uses wildcard/broad cloud permissions | C16: agentguard | D16: Native | E16: Authorization | F16: Critical | G16: config | H16: agent_runtime | L16: Runtime service account uses wildcard/broad cloud permissions | M16: IaC rule for agent workload identity with wildcard actions/resources or broad predefined admin roles. | N16: Least-privilege role scoped to approved tools/resources | O16: N/A | P16: IAM roles/actions/resources with wildcard/admin/editor/owner | Q16: rules/builtin/authorization.yaml | R16: https://github.com/akarshkn17/AgentGuard/blob/main/rules/builtin/authorization.yaml | S16: IAM_03 (Least-Privilege Resource-Scoped IAM); IAM_12 (Periodic Access Review & Recertification); REG_04 (Policy-as-Code Coverage for Must Controls); SEC_15 (Agent Registry Compliance Gate); IR_01 (Multi-Level Kill-Switch Model)
A17: AIR-AUTH-005 | B17: Tool allowlist is derived from model or user input | C17: agentguard | D17: Native | E17: Authorization | F17: Critical | G17: taint | H17: agent, tool | I17: llm_output, user_input | J17: policy_mutation | K17: allowlist | L17: Tool allowlist is derived from model or user input | M17: Flag tainted values mutating enabled/allowed tool lists. | N17: Server-side static/policy-derived allowlist | O17: User/model-selected tool names | P17: enabled_tools/allowed_tools/tool registry | Q17: rules/builtin/authorization.yaml | R17: https://github.com/akarshkn17/AgentGuard/blob/main/rules/builtin/authorization.yaml | S17: SEC_06 (Structured Output Schema + Tool Name Auth); REG_02 (Agent Manifest Schema Validation); SEC_21 (Policy-as-Code for AI Controls); MON_04 (Tool Invocation Monitoring + Auto-Response); IR_01 (Multi-Level Kill-Switch Model)
A18: AIR-AUTH-006 | B18: All registered tools exposed to model regardless of user role | C18: agentguard | D18: Native | E18: Authorization | F18: High | G18: config | H18: agent | L18: All registered tools exposed to model regardless of user role | M18: Flag sensitive tool set bound unconditionally in apps with multiple roles/tenants. | N18: Role/policy-filtered tool set | O18: User role/identity | P18: llm.bind_tools/tools=[all_tools]/agent executor | Q18: rules/builtin/authorization.yaml | R18: https://github.com/akarshkn17/AgentGuard/blob/main/rules/builtin/authorization.yaml | S18: IAM_03 (Least-Privilege Resource-Scoped IAM); IAM_04 (User Identity Propagation - AgentAuthContext); REG_02 (Agent Manifest Schema Validation); SEC_15 (Agent Registry Compliance Gate)
A19: AIR-AUTH-007 | B19: Sensitive action lacks step-up or human approval gate | C19: agentguard | D19: Native | E19: Authorization | F19: Critical | G19: control_flow | H19: agent, tool | I19: llm_output | K19: approval_gate | L19: Sensitive action lacks step-up or human approval gate | M19: Flag configured high-impact sinks directly reachable from model tool call without approval function/node. | N19: Explicit approval/policy node | O19: LLM tool-call decision | P19: delete/deploy/payment/email/admin/production side-effect | Q19: rules/builtin/authorization.yaml | R19: https://github.com/akarshkn17/AgentGuard/blob/main/rules/builtin/authorization.yaml | S19: SEC_18 (Human-in-the-Loop for High-Risk Actions); BIZ_02 (High-Risk Action Catalog); IAM_11 (Conditional Access for Agent Admin Operations); MON_03 (Decision Trace Logging - Tool, Policy and Evidence Trace)
A20: AIR-AUTH-008 | B20: Authorization result cached without user/resource scoping | C20: agentguard | D20: Native | E20: Authorization | F20: High | G20: config | H20: tool | L20: Authorization result cached without user/resource scoping | M20: Flag global/static allow cache or cache keyed only by tool/action. | N20: Cache key includes principal, action, resource, policy version | O20: Auth decision cache | P20: tool/resource access | Q20: rules/builtin/authorization.yaml | R20: https://github.com/akarshkn17/AgentGuard/blob/main/rules/builtin/authorization.yaml | S20: IAM_04 (User Identity Propagation - AgentAuthContext); IAM_03 (Least-Privilege Resource-Scoped IAM); MON_03 (Decision Trace Logging - Tool, Policy and Evidence Trace)
A21: AIR-CLOUD-001 | B21: Agent service account key embedded or mounted as static credential | C21: agentguard | D21: Native | E21: Cloud Config | F21: Critical | G21: secret | H21: agent_runtime | I21: sensitive_data | L21: Agent service account key embedded or mounted as static credential | M21: Detect cloud key JSON/private key files and static credential mounts in agent deployments. | N21: Workload identity / short-lived credentials | O21: Service-account key file/token | P21: container/env/secret volume/code | Q21: rules/builtin/cloud_config.yaml | R21: https://github.com/akarshkn17/AgentGuard/blob/main/rules/builtin/cloud_config.yaml | S21: IAM_02 (Workload Identity - Zero Static Key Files); ENC_01 (Secrets Retrieval via Platform Module - No Bypass); IAM_09 (Non-Human Identity (NHI) Lifecycle Management); SEC_11 (CI/CD Gates - Secret Scan, SAST, Signed Skills, Pinned Models)
A22: AIR-CLOUD-002 | B22: Agent container runs privileged or with host mounts | C22: agentguard | D22: Native | E22: Cloud Config | F22: Critical | G22: config | H22: agent_runtime | K22: path_containment | L22: Agent container runs privileged or with host mounts | M22: Kubernetes/Docker IaC rule scoped to AI agent/tool/MCP workloads. | N22: Restricted container security context | O22: N/A | P22: privileged:true, hostPath, docker.sock, hostNetwork/hostPID | Q22: rules/builtin/cloud_config.yaml | R22: https://github.com/akarshkn17/AgentGuard/blob/main/rules/builtin/cloud_config.yaml | S22: IAM_03 (Least-Privilege Resource-Scoped IAM); SEC_11 (CI/CD Gates - Secret Scan, SAST, Signed Skills, Pinned Models); REG_04 (Policy-as-Code Coverage for Must Controls)
A23: AIR-CLOUD-003 | B23: Agent workload has unrestricted outbound network egress | C23: agentguard | D23: Native | E23: Cloud Config | F23: High | G23: config | H23: agent_runtime | K23: allowlist | L23: Agent workload has unrestricted outbound network egress | M23: Flag agent/tool workloads with powerful data access and no egress restrictions; repository-level config rule. | N23: Egress allowlist/proxy/network policy | O23: N/A | P23: no NetworkPolicy/egress restriction where architecture expects isolation | Q23: rules/builtin/cloud_config.yaml | R23: https://github.com/akarshkn17/AgentGuard/blob/main/rules/builtin/cloud_config.yaml | S23: NET_06 (Per-Agent Egress Allowlist); NET_11 (Network Segmentation by Trust Tier); NET_12 (Data Exfiltration Perimeter (Egress DLP)); MON_11 (Security Threat Detection Integration)
A24: AIR-CLOUD-004 | B24: Publicly exposed agent/MCP/admin service without auth proxy | C24: agentguard | D24: Native | E24: Cloud Config | F24: Critical | G24: config | H24: agent_runtime | L24: Publicly exposed agent/MCP/admin service without auth proxy | M24: Correlate public ingress with service lacking app/auth middleware. | N24: Auth gateway/IAP/API gateway/private ingress | O24: Internet ingress | P24: LoadBalancer/Ingress/public endpoint to sensitive service | Q24: rules/builtin/cloud_config.yaml | R24: https://github.com/akarshkn17/AgentGuard/blob/main/rules/builtin/cloud_config.yaml | S24: NET_01 (WAF-Capable Edge for Every Agent); NET_04 (Private Origin Configuration); MCP_02 (MCP Authentication and Authorization); NET_09 (Geo & IP Allowlisting)
A25: AIR-EXEC-001 | B25: LLM or user input reaches shell command execution | C25: agentguard | D25: Native | E25: Code Execution | F25: Critical | G25: taint | H25: tool, agent | I25: user_input, llm_output, tool_result, retrieval | J25: shell_execution | K25: allowlist | L25: LLM or user input reaches shell command execution | M25: Source-to-sink taint rule; treat string formatting into shell commands as exploitable. | N25: Argument arrays, allowlisted commands, no shell interpolation | O25: User input, model output, tool args, retrieved content | P25: os.system, subprocess.* with shell=True, child_process.exec, execSync, spawn with shell | Q25: rules/builtin/code_execution.yaml | R25: https://github.com/akarshkn17/AgentGuard/blob/main/rules/builtin/code_execution.yaml | S25: SEC_11 (CI/CD Gates - Secret Scan, SAST, Signed Skills, Pinned Models); MON_04 (Tool Invocation Monitoring + Auto-Response); SEC_06 (Structured Output Schema + Tool Name Auth); SEC_18 (Human-in-the-Loop for High-Risk Actions)
A26: AIR-EXEC-002 | B26: LLM or user input reaches eval/exec | C26: agentguard | D26: Native | E26: Code Execution | F26: Critical | G26: taint | H26: tool, agent | I26: user_input, llm_output, tool_result, retrieval | J26: dynamic_code | K26: allowlist | L26: LLM or user input reaches eval/exec | M26: Flag any untrusted source reaching dynamic language execution. | N26: No dynamic code execution; parser/allowlist instead | O26: User/model/tool/retrieval content | P26: eval, exec, compile+exec, Function(), vm.runIn* | Q26: rules/builtin/code_execution.yaml | R26: https://github.com/akarshkn17/AgentGuard/blob/main/rules/builtin/code_execution.yaml | S26: SEC_11 (CI/CD Gates - Secret Scan, SAST, Signed Skills, Pinned Models); MON_04 (Tool Invocation Monitoring + Auto-Response); SEC_06 (Structured Output Schema + Tool Name Auth); SEC_18 (Human-in-the-Loop for High-Risk Actions)
A27: AIR-EXEC-003 | B27: Dynamic import/module loading from untrusted input | C27: agentguard | D27: Native | E27: Code Execution | F27: High | G27: taint | H27: tool, agent | I27: llm_output, path_input, user_input | K27: allowlist | L27: Dynamic import/module loading from untrusted input | M27: Flag untrusted module/package name reaching dynamic import API. | N27: Allowlisted module identifiers | O27: User/model/tool-controlled module/package/path | P27: importlib.import_module, __import__, require(), dynamic import() | Q27: rules/builtin/code_execution.yaml | R27: https://github.com/akarshkn17/AgentGuard/blob/main/rules/builtin/code_execution.yaml | S27: SEC_11 (CI/CD Gates - Secret Scan, SAST, Signed Skills, Pinned Models); MON_04 (Tool Invocation Monitoring + Auto-Response); SEC_06 (Structured Output Schema + Tool Name Auth); SEC_18 (Human-in-the-Loop for High-Risk Actions)
A28: AIR-EXEC-004 | B28: LLM or user input reaches SQL query construction | C28: agentguard | D28: Native | E28: Injection | F28: Critical | G28: taint | H28: tool, agent | I28: user_input, llm_output | J28: sql_query | L28: LLM or user input reaches SQL query construction | M28: Flag tainted value concatenated/interpolated into SQL passed to execution sink. | N28: Parameterized queries / query builder | O28: User input, model output, tool args | P28: cursor.execute/query/raw SQL/string SQL APIs | Q28: rules/builtin/injection.yaml | R28: https://github.com/akarshkn17/AgentGuard/blob/main/rules/builtin/injection.yaml | S28: SEC_11 (CI/CD Gates - Secret Scan, SAST, Signed Skills, Pinned Models); MON_04 (Tool Invocation Monitoring + Auto-Response); SEC_06 (Structured Output Schema + Tool Name Auth); IR_01 (Multi-Level Kill-Switch Model)
A29: AIR-EXEC-005 | B29: LLM or user input reaches NoSQL/graph query object unsafely | C29: agentguard | D29: Native | E29: Injection | F29: High | G29: taint | H29: tool, agent | I29: llm_output, user_input | K29: allowlist, schema_validation | L29: LLM or user input reaches NoSQL/graph query object unsafely | M29: Flag tainted object/operator keys such as $where/$regex/script or raw graph query strings. | N29: Schema + operator allowlist; parameterized query APIs | O29: User/model/tool-controlled filters/operators | P29: Mongo find/update, Elasticsearch query DSL, Cypher/Gremlin raw query | Q29: rules/builtin/injection.yaml | R29: https://github.com/akarshkn17/AgentGuard/blob/main/rules/builtin/injection.yaml | S29: SEC_11 (CI/CD Gates - Secret Scan, SAST, Signed Skills, Pinned Models); MON_04 (Tool Invocation Monitoring + Auto-Response); SEC_06 (Structured Output Schema + Tool Name Auth)
A30: AIR-EXEC-006 | B30: LLM output reaches template engine with code-capable expressions | C30: agentguard | D30: Native | E30: Injection | F30: Critical | G30: taint | H30: tool, agent | I30: llm_output, user_input | L30: LLM output reaches template engine with code-capable expressions | M30: Flag untrusted content used as template source rather than template data. | N30: Sandboxed template + fixed template source | O30: Model/user/tool content | P30: Jinja2 Template/from_string, render_template_string, EJS/Pug/Handlebars unsafe helpers | Q30: rules/builtin/injection.yaml | R30: https://github.com/akarshkn17/AgentGuard/blob/main/rules/builtin/injection.yaml | S30: SEC_11 (CI/CD Gates - Secret Scan, SAST, Signed Skills, Pinned Models); MON_04 (Tool Invocation Monitoring + Auto-Response); SEC_06 (Structured Output Schema + Tool Name Auth); SEC_18 (Human-in-the-Loop for High-Risk Actions)
A31: AIR-EXEC-007 | B31: Downloaded content executed without integrity verification | C31: agentguard | D31: Native | E31: Code Execution | F31: Critical | G31: taint | H31: tool, skill | I31: url_input | J31: shell_execution | K31: signature_verification | L31: Downloaded content executed without integrity verification | M31: Detect download-to-execute chains and curl|bash / wget|sh patterns. | N31: Checksum/signature verification and trusted origin | O31: HTTP download, curl/wget, remote URL, package artifact | P31: shell execution, chmod+execute, python/node/bash invocation | Q31: rules/builtin/code_execution.yaml | R31: https://github.com/akarshkn17/AgentGuard/blob/main/rules/builtin/code_execution.yaml | S31: SEC_11 (CI/CD Gates - Secret Scan, SAST, Signed Skills, Pinned Models); MON_04 (Tool Invocation Monitoring + Auto-Response); SEC_20 (AIBOM - AI Bill of Materials); REG_03 (AIBOM Required for Every Agent); REG_05 (Agent Risk Tiering and Promotion Workflow); IR_01 (Multi-Level Kill-Switch Model)
A32: AIR-EXEC-008 | B32: Skill installs and executes unpinned package at runtime | C32: agentguard | D32: Native | E32: Code Execution | F32: High | G32: dependency | H32: skill, plugin | L32: Skill installs and executes unpinned package at runtime | M32: Flag pip install pkg, npm install pkg, npx pkg without exact version/digest inside skills/tools. | N32: Pinned version + lockfile + trusted registry | O32: pip/npm/uv/npx/package install command in skill/tool | P32: runtime execution/import of installed package | Q32: rules/builtin/code_execution.yaml | R32: https://github.com/akarshkn17/AgentGuard/blob/main/rules/builtin/code_execution.yaml | S32: SEC_11 (CI/CD Gates - Secret Scan, SAST, Signed Skills, Pinned Models); MON_04 (Tool Invocation Monitoring + Auto-Response); SEC_20 (AIBOM - AI Bill of Materials); REG_03 (AIBOM Required for Every Agent); REG_05 (Agent Risk Tiering and Promotion Workflow)
A33: AIR-EXEC-009 | B33: User or model-controlled interpreter selection | C33: agentguard | D33: Native | E33: Code Execution | F33: Critical | G33: taint | H33: tool | I33: path_input, user_input | J33: dynamic_code, shell_execution | K33: allowlist | L33: User or model-controlled interpreter selection | M33: Flag tainted executable/program argument at process-creation sink. | N33: Fixed executable allowlist | O33: Interpreter/runtime name or executable path from input | P33: subprocess/exec/spawn | Q33: rules/builtin/code_execution.yaml | R33: https://github.com/akarshkn17/AgentGuard/blob/main/rules/builtin/code_execution.yaml | S33: SEC_11 (CI/CD Gates - Secret Scan, SAST, Signed Skills, Pinned Models); MON_04 (Tool Invocation Monitoring + Auto-Response); SEC_06 (Structured Output Schema + Tool Name Auth); SEC_18 (Human-in-the-Loop for High-Risk Actions)
A34: AIR-FILE-001 | B34: Model-controlled path reaches file read | C34: agentguard | D34: Native | E34: File Access | F34: High | G34: taint | H34: tool, agent | I34: user_input, llm_output, path_input | J34: file_read | L34: Model-controlled path reaches file read | M34: Flag tainted path at read sink without resolve+root containment check. | N34: Canonicalize + restrict to approved root | O34: Model/user/tool path | P34: open/readFile/read_text/send_file/file loader | Q34: rules/builtin/file_access.yaml | R34: https://github.com/akarshkn17/AgentGuard/blob/main/rules/builtin/file_access.yaml | S34: SEC_11 (CI/CD Gates - Secret Scan, SAST, Signed Skills, Pinned Models); MON_04 (Tool Invocation Monitoring + Auto-Response)
A35: AIR-FILE-002 | B35: Model-controlled path reaches file write/delete | C35: agentguard | D35: Native | E35: File Access | F35: Critical | G35: taint | H35: tool, agent | I35: user_input, llm_output, path_input | J35: file_write | L35: Model-controlled path reaches file write/delete | M35: Flag tainted path at write/delete sink without containment policy. | N35: Canonicalize + approved writable root + deny sensitive paths | O35: Model/user/tool path | P35: open(write), writeFile, unlink/remove/rmtree, rename | Q35: rules/builtin/file_access.yaml | R35: https://github.com/akarshkn17/AgentGuard/blob/main/rules/builtin/file_access.yaml | S35: SEC_11 (CI/CD Gates - Secret Scan, SAST, Signed Skills, Pinned Models); SEC_18 (Human-in-the-Loop for High-Risk Actions); MON_04 (Tool Invocation Monitoring + Auto-Response)
A36: AIR-FILE-003 | B36: Arbitrary local URI loader permits file disclosure | C36: agentguard | D36: Native | E36: File Access | F36: High | G36: taint | H36: tool, rag | I36: llm_output, url_input, user_input | J36: file_read | K36: allowlist | L36: Arbitrary local URI loader permits file disclosure | M36: Flag user/model URI entering loader that supports file:// or local paths. | N36: Allowlisted schemes and roots | O36: User/model-controlled URI | P36: file:// loader, generic URL/file loader, document loader | Q36: rules/builtin/file_access.yaml | R36: https://github.com/akarshkn17/AgentGuard/blob/main/rules/builtin/file_access.yaml | S36: SEC_11 (CI/CD Gates - Secret Scan, SAST, Signed Skills, Pinned Models); MON_04 (Tool Invocation Monitoring + Auto-Response)
A37: AIR-FILE-004 | B37: Unsafe archive extraction permits Zip Slip | C37: agentguard | D37: Native | E37: Archive | F37: High | G37: taint | H37: tool, skill | L37: Unsafe archive extraction permits Zip Slip | M37: Flag archive extraction without member path containment validation. | N37: Validate each extracted path remains under destination | O37: Uploaded/downloaded archive | P37: extractall/unzip/tar extraction | Q37: rules/builtin/archive.yaml | R37: https://github.com/akarshkn17/AgentGuard/blob/main/rules/builtin/archive.yaml | S37: SEC_11 (CI/CD Gates - Secret Scan, SAST, Signed Skills, Pinned Models); MON_04 (Tool Invocation Monitoring + Auto-Response)
A38: AIR-FILE-005 | B38: Uploaded executable/script content stored in executable location | C38: agentguard | D38: Native | E38: File Upload | F38: Critical | G38: taint | H38: tool, agent | I38: retrieval | L38: Uploaded executable/script content stored in executable location | M38: Flag uploads written into directories later imported/executed or served as executable content. | N38: Extension/content validation + non-executable storage | O38: User/tool file upload | P38: web root, plugin/skill directory, executable workspace | Q38: rules/builtin/file_upload.yaml | R38: https://github.com/akarshkn17/AgentGuard/blob/main/rules/builtin/file_upload.yaml | S38: SEC_11 (CI/CD Gates - Secret Scan, SAST, Signed Skills, Pinned Models); SEC_10 (Document Screening for File-Typed Outputs); MON_04 (Tool Invocation Monitoring + Auto-Response); IR_01 (Multi-Level Kill-Switch Model)
A39: AIR-FILE-006 | B39: Skill scans broad filesystem or home directory for secrets | C39: agentguard | D39: Native | E39: File Access | F39: High | G39: structural | H39: skill, agent | K39: allowlist | L39: Skill scans broad filesystem or home directory for secrets | M39: Flag skill/tool instructions or code that enumerate known credential paths without a narrow documented target. | N39: Explicit narrow file allowlist | O39: Skill/tool logic | P39: ~/.ssh, ~/.aws, ~/.config, .env, credentials files, recursive home scan | Q39: rules/builtin/file_access.yaml | R39: https://github.com/akarshkn17/AgentGuard/blob/main/rules/builtin/file_access.yaml | S39: SEC_11 (CI/CD Gates - Secret Scan, SAST, Signed Skills, Pinned Models); ENC_01 (Secrets Retrieval via Platform Module - No Bypass); DATA_03 (DLP at Prompt Assembly Time); MON_04 (Tool Invocation Monitoring + Auto-Response)
A40: AIR-MCP-001 | B40: MCP server exposed over plaintext HTTP | C40: agentguard | D40: Native | E40: MCP | F40: High | G40: config | H40: mcp_server | K40: tls_validation | L40: MCP server exposed over plaintext HTTP | M40: Flag network MCP server configured with plaintext remote listener; exempt loopback/local development by policy. | N40: TLS or trusted local-only transport | O40: N/A | P40: http:// listener / SSE or streamable HTTP without TLS termination requirement | Q40: rules/builtin/mcp.yaml | R40: https://github.com/akarshkn17/AgentGuard/blob/main/rules/builtin/mcp.yaml | S40: NET_03 (TLS 1.2+ End-to-End); MCP_01 (Approved MCP Server Registry); SEC_22 (Formal MCP Server Security Review); MCP_04 (MCP Network Isolation and Egress Control)
...

Sheet entity
A1: Entity_Type | B1: What it represents | C1: Typical discovery evidence | D1: Version signal
A2: agent | B2: LLM-backed autonomous or semi-autonomous agent | C2: Agent()/RealtimeAgent()/framework agent constructor, agent config | D2: Definition hash + framework/model version + Git commit
A3: sub_agent | B3: Agent invoked/delegated by another agent | C3: handoffs, graph nodes, agents-as-tools, delegation config | D3: Definition hash + parent relationship + Git commit
A4: orchestrator | B4: Coordinator/planner/router supervising agents | C4: StateGraph/supervisor/router/planner constructs | D4: Graph/config hash + framework version
A5: tool | B5: Local function/API callable by an agent | C5: @tool, @function_tool, tool wrappers, bound tool lists | D5: Function hash + schema/signature hash
A6: function_tool | B6: Function-call tool with typed schema | C6: SDK function-tool decorators / JSON schema | D6: Function + schema hash
A7: mcp_server | B7: Model Context Protocol server | C7: MCPServer / legacy FastMCP / MCP server config | D7: Server definition hash + MCP package/spec version
A8: mcp_client | B8: MCP client connection/integration | C8: stdio/Streamable HTTP/SSE client creation | D8: Endpoint/config hash + MCP package version
A9: mcp_tool | B9: Tool exposed by an MCP server | C9: @mcp.tool / @server.tool | D9: Function/schema hash
A10: mcp_resource | B10: Resource exposed by MCP | C10: @mcp.resource / resources config | D10: Resource handler/template hash
A11: mcp_prompt | B11: Prompt exposed by MCP | C11: @mcp.prompt / prompt config | D11: Prompt handler/template hash
A12: skill | B12: Skill/instruction bundle consumed by an agent | C12: SKILL.md, skill YAML/JSON, referenced scripts | D12: Skill content hash + referenced artifact hashes
... A29: remote_agent | B29: Externally hosted/remote agent capability | C29: agent endpoint, remote agent config/card | D29: Endpoint + advertised capability/version

Sheet Source Summary
A1: Source File | B1: Engine | C1: Rule Set | D1: Rule Count | E1: Critical | F1: High | G1: Medium | H1: Low
A2: rules/custom/example.yaml | B2: agentguard | C2: Custom | D2: =COUNTIF('Risk_rule Catalog'!$Q$2:$Q$182,A2) -> 1 | E2: =COUNTIFS('Risk_rule Catalog'!$Q$2:$Q$182,A2,'Risk_rule Catalog'!$F$2:$F$182,"Critical") -> 1 | F2: =COUNTIFS('Risk_rule Catalog'!$Q$2:$Q$182,A2,'Risk_rule Catalog'!$F$2:$F$182,"High") -> 0 | G2: =COUNTIFS('Risk_rule Catalog'!$Q$2:$Q$182,A2,'Risk_rule Catalog'!$F$2:$F$182,"Medium") -> 0 | H2: =COUNTIFS('Risk_rule Catalog'!$Q$2:$Q$182,A2,'Risk_rule Catalog'!$F$2:$F$182,"Low") -> 0
A3: rules/integrations/skillspector.yaml | B3: skillspector | C3: Integration | D3: =COUNTIF('Risk_rule Catalog'!$Q$2:$Q$182,A3) -> 68 | E3: =COUNTIFS('Risk_rule Catalog'!$Q$2:$Q$182,A3,'Risk_rule Catalog'!$F$2:$F$182,"Critical") -> 8 | F3: =COUNTIFS('Risk_rule Catalog'!$Q$2:$Q$182,A3,'Risk_rule Catalog'!$F$2:$F$182,"High") -> 36 | G3: =COUNTIFS('Risk_rule Catalog'!$Q$2:$Q$182,A3,'Risk_rule Catalog'!$F$2:$F$182,"Medium") -> 21 | H3: =COUNTIFS('Risk_rule Catalog'!$Q$2:$Q$182,A3,'Risk_rule Catalog'!$F$2:$F$182,"Low") -> 3
A4: rules/builtin/agent_orchestration.yaml | B4: agentguard | C4: Native | D4: =COUNTIF('Risk_rule Catalog'!$Q$2:$Q$182,A4) -> 10 | E4: =COUNTIFS('Risk_rule Catalog'!$Q$2:$Q$182,A4,'Risk_rule Catalog'!$F$2:$F$182,"Critical") -> 4 | F4: =COUNTIFS('Risk_rule Catalog'!$Q$2:$Q$182,A4,'Risk_rule Catalog'!$F$2:$F$182,"High") -> 5 | G4: =COUNTIFS('Risk_rule Catalog'!$Q$2:$Q$182,A4,'Risk_rule Catalog'!$F$2:$F$182,"Medium") -> 1 | H4: =COUNTIFS('Risk_rule Catalog'!$Q$2:$Q$182,A4,'Risk_rule Catalog'!$F$2:$F$182,"Low") -> 0
A5: rules/builtin/archive.yaml | B5: agentguard | C5: Native | D5: =COUNTIF('Risk_rule Catalog'!$Q$2:$Q$182,A5) -> 1 | E5: =COUNTIFS('Risk_rule Catalog'!$Q$2:$Q$182,A5,'Risk_rule Catalog'!$F$2:$F$182,"Critical") -> 0 | F5: =COUNTIFS('Risk_rule Catalog'!$Q$2:$Q$182,A5,'Risk_rule Catalog'!$F$2:$F$182,"High") -> 1 | G5: =COUNTIFS('Risk_rule Catalog'!$Q$2:$Q$182,A5,'Risk_rule Catalog'!$F$2:$F$182,"Medium") -> 0 | H5: =COUNTIFS('Risk_rule Catalog'!$Q$2:$Q$182,A5,'Risk_rule Catalog'!$F$2:$F$182,"Low") -> 0
A6: rules/builtin/authorization.yaml | B6: agentguard | C6: Native | D6: =COUNTIF('Risk_rule Catalog'!$Q$2:$Q$182,A6) -> 7 | E6: =COUNTIFS('Risk_rule Catalog'!$Q$2:$Q$182,A6,'Risk_rule Catalog'!$F$2:$F$182,"Critical") -> 5 | F6: =COUNTIFS('Risk_rule Catalog'!$Q$2:$Q$182,A6,'Risk_rule Catalog'!$F$2:$F$182,"High") -> 2 | G6: =COUNTIFS('Risk_rule Catalog'!$Q$2:$Q$182,A6,'Risk_rule Catalog'!$F$2:$F$182,"Medium") -> 0 | H6: =COUNTIFS('Risk_rule Catalog'!$Q$2:$Q$182,A6,'Risk_rule Catalog'!$F$2:$F$182,"Low") -> 0
A7: rules/builtin/cloud_config.yaml | B7: agentguard | C7: Native | D7: =COUNTIF('Risk_rule Catalog'!$Q$2:$Q$182,A7) -> 4 | E7: =COUNTIFS('Risk_rule Catalog'!$Q$2:$Q$182,A7,'Risk_rule Catalog'!$F$2:$F$182,"Critical") -> 3 | F7: =COUNTIFS('Risk_rule Catalog'!$Q$2:$Q$182,A7,'Risk_rule Catalog'!$F$2:$F$182,"High") -> 1 | G7: =COUNTIFS('Risk_rule Catalog'!$Q$2:$Q$182,A7,'Risk_rule Catalog'!$F$2:$F$182,"Medium") -> 0 | H7: =COUNTIFS('Risk_rule Catalog'!$Q$2:$Q$182,A7,'Risk_rule Catalog'!$F$2:$F$182,"Low") -> 0
A8: rules/builtin/code_execution.yaml | B8: agentguard | C8: Native | D8: =COUNTIF('Risk_rule Catalog'!$Q$2:$Q$182,A8) -> 6 | E8: =COUNTIFS('Risk_rule Catalog'!$Q$2:$Q$182,A8,'Risk_rule Catalog'!$F$2:$F$182,"Critical") -> 4 | F8: =COUNTIFS('Risk_rule Catalog'!$Q$2:$Q$182,A8,'Risk_rule Catalog'!$F$2:$F$182,"High") -> 2 | G8: =COUNTIFS('Risk_rule Catalog'!$Q$2:$Q$182,A8,'Risk_rule Catalog'!$F$2:$F$182,"Medium") -> 0 | H8: =COUNTIFS('Risk_rule Catalog'!$Q$2:$Q$182,A8,'Risk_rule Catalog'!$F$2:$F$182,"Low") -> 0
A9: rules/builtin/data_exfiltration.yaml | B9: agentguard | C9: Native | D9: =COUNTIF('Risk_rule Catalog'!$Q$2:$Q$182,A9) -> 1 | E9: =COUNTIFS('Risk_rule Catalog'!$Q$2:$Q$182,A9,'Risk_rule Catalog'!$F$2:$F$182,"Critical") -> 1 | F9: =COUNTIFS('Risk_rule Catalog'!$Q$2:$Q$182,A9,'Risk_rule Catalog'!$F$2:$F$182,"High") -> 0 | G9: =COUNTIFS('Risk_rule Catalog'!$Q$2:$Q$182,A9,'Risk_rule Catalog'!$F$2:$F$182,"Medium") -> 0 | H9: =COUNTIFS('Risk_rule Catalog'!$Q$2:$Q$182,A9,'Risk_rule Catalog'!$F$2:$F$182,"Low") -> 0
A10: rules/builtin/debug_exposure.yaml | B10: agentguard | C10: Native | D10: =COUNTIF('Risk_rule Catalog'!$Q$2:$Q$182,A10) -> 1 | E10: =COUNTIFS('Risk_rule Catalog'!$Q$2:$Q$182,A10,'Risk_rule Catalog'!$F$2:$F$182,"Critical") -> 0 | F10: =COUNTIFS('Risk_rule Catalog'!$Q$2:$Q$182,A10,'Risk_rule Catalog'!$F$2:$F$182,"High") -> 1 | G10: =COUNTIFS('Risk_rule Catalog'!$Q$2:$Q$182,A10,'Risk_rule Catalog'!$F$2:$F$182,"Medium") -> 0 | H10: =COUNTIFS('Risk_rule Catalog'!$Q$2:$Q$182,A10,'Risk_rule Catalog'!$F$2:$F$182,"Low") -> 0
A11: rules/builtin/deserialization.yaml | B11: agentguard | C11: Native | D11: =COUNTIF('Risk_rule Catalog'!$Q$2:$Q$182,A11) -> 2 | E11: =COUNTIFS('Risk_rule Catalog'!$Q$2:$Q$182,A11,'Risk_rule Catalog'!$F$2:$F$182,"Critical") -> 1 | F11: =COUNTIFS('Risk_rule Catalog'!$Q$2:$Q$182,A11,'Risk_rule Catalog'!$F$2:$F$182,"High") -> 1 | G11: =COUNTIFS('Risk_rule Catalog'!$Q$2:$Q$182,A11,'Risk_rule Catalog'!$F$2:$F$182,"Medium") -> 0 | H11: =COUNTIFS('Risk_rule Catalog'!$Q$2:$Q$182,A11,'Risk_rule Catalog'!$F$2:$F$182,"Low") -> 0
A12: rules/builtin/file_access.yaml | B12: agentguard | C12: Native | D12: =COUNTIF('Risk_rule Catalog'!$Q$2:$Q$182,A12) -> 4 | E12: =COUNTIFS('Risk_rule Catalog'!$Q$2:$Q$182,A12,'Risk_rule Catalog'!$F$2:$F$182,"Critical") -> 1 | F12: =COUNTIFS('Risk_rule Catalog'!$Q$2:$Q$182,A12,'Risk_rule Catalog'!$F$2:$F$182,"High") -> 3 | G12: =COUNTIFS('Risk_rule Catalog'!$Q$2:$Q$182,A12,'Risk_rule Catalog'!$F$2:$F$182,"Medium") -> 0 | H12: =COUNTIFS('Risk_rule Catalog'!$Q$2:$Q$182,A12,'Risk_rule Catalog'!$F$2:$F$182,"Low") -> 0
A13: rules/builtin/file_upload.yaml | B13: agentguard | C13: Native | D13: =COUNTIF('Risk_rule Catalog'!$Q$2:$Q$182,A13) -> 1 | E13: =COUNTIFS('Risk_rule Catalog'!$Q$2:$Q$182,A13,'Risk_rule Catalog'!$F$2:$F$182,"Critical") -> 1 | F13: =COUNTIFS('Risk_rule Catalog'!$Q$2:$Q$182,A13,'Risk_rule Catalog'!$F$2:$F$182,"High") -> 0 | G13: =COUNTIFS('Risk_rule Catalog'!$Q$2:$Q$182,A13,'Risk_rule Catalog'!$F$2:$F$182,"Medium") -> 0 | H13: =COUNTIFS('Risk_rule Catalog'!$Q$2:$Q$182,A13,'Risk_rule Catalog'!$F$2:$F$182,"Low") -> 0
... A27: rules/builtin/tls.yaml | B27: agentguard | C27: Native | D27: =COUNTIF('Risk_rule Catalog'!$Q$2:$Q$182,A27) -> 1 | E27: =COUNTIFS('Risk_rule Catalog'!$Q$2:$Q$182,A27,'Risk_rule Catalog'!$F$2:$F$182,"Critical") -> 0 | F27: =COUNTIFS('Risk_rule Catalog'!$Q$2:$Q$182,A27,'Risk_rule Catalog'!$F$2:$F$182,"High") -> 1 | G27: =COUNTIFS('Risk_rule Catalog'!$Q$2:$Q$182,A27,'Risk_rule Catalog'!$F$2:$F$182,"Medium") -> 0 | H27: =COUNTIFS('Risk_rule Catalog'!$Q$2:$Q$182,A27,'Risk_rule Catalog'!$F$2:$F$182,"Low") -> 0
